Workbook

Sheet customers
A1: customer_id | B1: customer_name | C1: segment | D1: city | E1: country | F1: signup_date
A2: C0001 | B2: House and Sons | C2: Consumer | D2: South Todd | E2: Latvia | F2: 44807
A3: C0002 | B3: Barrera-Martin | C3: Consumer | D3: South Josephmouth | E3: Sweden | F3: 44935
A4: C0003 | B4: Bernard, Cowan and Peters | C4: Consumer | D4: Mooreport | E4: Estonia | F4: 44814
A5: C0004 | B5: Noah Brown | C5: SME | D5: Brianshire | E5: Poland | F5: 45279
A6: C0005 | B6: Moore, Yu and Miller | C6: SME | D6: North Brooke | E6: Sweden | F6: 45636
A7: C0006 | B7: Powell PLC | C7: SME | D7: New Brooke | E7: Latvia | F7: 45536
A8: C0007 | B8: Sandoval-Cunningham | C8: SME | D8: Sarahborough | E8: Netherlands | F8: 45626
A9: C0008 | B9: Allen-Foster | C9: Enterprise | D9: Stephenland | E9: Sweden | F9: 44439
A10: C0009 | B10: Murillo, Ferrell and Jones | C10: SME | D10: New Joseph | E10: Lithuania | F10: 46100
A11: C0010 | B11: Suarez LLC | C11: Consumer | D11: Ericside | E11: Estonia | F11: 45687
A12: C0011 | B12: Riggs, Roman and Rice | C12: Consumer | D12: Sarahville | E12: Netherlands | F12: 46110
A13: C0012 | B13: Brian Rodriguez | C13: Consumer | D13: West Juan | E13: Poland | F13: 44801
... A301: C0300 | B301: Johnny Brown | C301: SME | D301: Hillport | E301: Poland | F301: 45293

Sheet inventory_snapshots
A1: warehouse_id | B1: product_id | C1: snapshot_date | D1: stock_on_hand | E1: reorder_point
A2: WH01 | B2: P0104 | C2: 44957 | D2: 243 | E2: 172
A3: WH01 | B3: P0023 | C3: 44957 | D3: 961 | E3: 263
A4: WH01 | B4: P0033 | C4: 44957 | D4: 1140 | E4: 175
A5: WH01 | B5: P0013 | C5: 44957 | D5: 677 | E5: 59
A6: WH01 | B6: P0124 | C6: 44957 | D6: 840 | E6: 202
A7: WH01 | B7: P0175 | C7: 44957 | D7: 770 | E7: 236
A8: WH01 | B8: P0166 | C8: 44957 | D8: 1030 | E8: 130
A9: WH01 | B9: P0150 | C9: 44957 | D9: 783 | E9: 59
A10: WH01 | B10: P0171 | C10: 44957 | D10: 661 | E10: 201
A11: WH01 | B11: P0042 | C11: 44957 | D11: 1056 | E11: 63
A12: WH01 | B12: P0188 | C12: 44957 | D12: 228 | E12: 207
A13: WH01 | B13: P0140 | C13: 44957 | D13: 947 | E13: 296
... A19255: WH10 | B19255: P0066 | C19255: 45626 | D19255: 709 | E19255: 295

Sheet orders
A1: order_id | B1: customer_id | C1: order_date | D1: order_priority | E1: region
A2: ORD000104 | B2: C0275 | C2: 45387 | D2: Economy
A3: ORD000258 | B3: C0236 | C3: 45274 | D3: Standard
A4: ORD003300 | B4: C0068 | C4: 44991 | D4: Express
A5: ORD003057 | B5: C0146 | C5: 45321 | D5: Express
A6: ORD000697 | B6: C0104 | C6: 45237 | D6: Economy
A7: ORD004047 | B7: C0181 | C7: 45618 | D7: standard
A8: ORD005666 | B8: C0111 | C8: 45308 | D8: Economy
A9: ORD003739 | B9: C0091 | C9: 44983 | D9: Express
A10: ORD003779 | B10: C0239 | C10: 45003 | D10: Standard
A11: ORD002570 | B11: C0026 | C11: 45541 | D11: EXPRESS
A12: ORD003191 | B12: C0270 | C12: 45227 | D12: Express
A13: ORD002284 | B13: C0119 | C13: 45509 | D13: Standard
... A16: ORD000802 | B16: C0007 | C16: 45466 | D16: standard
A17: ORD005834 | C17: 45233 | D17: same day
A18: ORD000840 | B18: C0038 | C18: 45311 | D18: Express
A19: ORD000004 | B19: C0196 | C19: 45588 | D19: Same Day
A20: ORD005195 | B20: C0204 | C20: 45485 | D20: Same Day
A21: ORD000910 | B21: C0194 | C21: 45295 | D21: Standard
A22: ORD005909 | B22: C0135 | C22: 45244 | D22: Express
A23: ORD004418 | B23: C0137 | C23: 45094 | D23: Same Day
A24: ORD000563 | B24: C0203 | C24: 45035 | D24: STANDARD
A25: ORD000289 | B25: C0225 | C25: 45031 | D25: Standard
A26: ORD005641 | B26: C0174 | C26: 45346 | D26: Express
A27: ORD005650 | B27: C0268 | C27: 45041 | D27: Same Day
A28: ORD003814 | B28: C0223 | C28: 44984 | D28: Standard
A29: ORD003176 | B29: C0270 | C29: 45239 | D29: Standard
... A34: ORD001126 | B34: C0010 | C34: 45070 | D34: Express
A35: ORD002483 | C35: 45144 | D35: Standard
A36: ORD002449 | B36: C0149 | C36: 45460 | D36: Standard
A37: ORD004155 | B37: C0085 | C37: 45149 | D37: Economy
A38: ORD005273 | B38: C0226 | C38: 45215 | D38: Express
A39: ORD001381 | B39: C0096 | C39: 45304 | D39: Express
A40: ORD004066 | B40: C0267 | C40: 45390 | D40: Same Day
A41: ORD004746 | B41: C0233 | C41: 45024 | D41: Same Day
A42: ORD005990 | B42: C0261 | C42: 45231 | D42: Standard
A43: ORD001146 | B43: C0090 | C43: 45316 | D43: Standard
A44: ORD000214 | B44: C0079 | C44: 45372 | D44: Standard
A45: ORD005496 | B45: C0003 | C45: 45043 | D45: Express
A46: ORD001692 | B46: C0059 | C46: 45317 | D46: Standard
...

Sheet products
A1: product_id | B1: product_name | C1: category | D1: sub_category | E1: supplier_id | F1: unit_cost | G1: unit_price
A2: P0001 | B2: Winter Sports Image Max | C2: Outdoor & Sports | D2: Winter Sports | E2: SUP009 | F2: 221.4 | G2: 440.43
A3: P0002 | B3: Small Appliances I | C3: Home & Kitchen | D3: Small Appliances | E3: SUP019 | F3: 186.76 | G3: 349.21
A4: P0003 | B4: Winter Sports Pick Max | C4: Outdoor & Sports | D4: Winter Sports | E4: SUP017 | F4: 91.78 | G4: 219.99
A5: P0004 | B5: Camping Gear Management Max | C5: Outdoor & Sports | D5: Camping Gear | E5: SUP021 | F5: 189.43 | G5: 424.37
A6: P0005 | B6: Lighting Newspaper Basic | C6: Home & Kitchen | D6: Lighting | E6: SUP015 | F6: 149.91 | G6: 253.72
A7: P0006 | B7: Personal Care Enter Pro | C7: Health & Beauty | D7: Personal Care | E7: SUP022 | F7: 242.83 | G7: 543.91
A8: P0007 | B8: Speakers On Lite | C8: Electronics | D8: Speakers | E8: SUP004 | F8: 188.22 | G8: 401.64
A9: P0008 | B9: Filing Traditional | C9: Office Supplies | D9: Filing | E9: SUP024 | F9: 41.22 | G9: 51.68
A10: P0009 | B10: Desk Accessories Yes | C10: Office Supplies | D10: Desk Accessories | E10: SUP010 | F10: 127.91 | G10: 175.54 | I10: Row Labels | J10: Average of unit_cost | K10: Average of unit_price | L10: Margin
A11: P0010 | B11: Wellness Activity Max | C11: Health & Beauty | D11: Wellness | E11: SUP018 | F11: 51.33 | G11: 86.23 | I11: Electronics | J11: 126.386 | K11: 230.63886 | L11: =GETPIVOTDATA("Average of unit_price",$I$10,"category","Electronics")-GETPIVOTDATA("Average of unit_cost",$I$10,"category","Electronics") -> 104.25286
A12: P0011 | B12: Skincare Response Pro | C12: Health & Beauty | D12: Skincare | E12: SUP012 | F12: 150.54 | G12: 272.76 | I12: Health & Beauty | J12: 152.93889 | K12: 275.7025 | L12: =GETPIVOTDATA("Average of unit_price",$I$10,"category","Health & Beauty")-GETPIVOTDATA("Average of unit_cost",$I$10,"category","Health & Beauty") -> 122.76361
A13: P0012 | B13: Desk Accessories Set Pro | C13: Office Supplies | D13: Desk Accessories | E13: SUP003 | F13: 16.37 | G13: 36.99 | I13: Home & Kitchen | J13: 132.9625 | K13: 245.475 | L13: =GETPIVOTDATA("Average of unit_price",$I$10,"category","Home & Kitchen")-GETPIVOTDATA("Average of unit_cost",$I$10,"category","Home & Kitchen") -> 112.5125
A14: P0013 | B14: Camping Gear Building Max | C14: Outdoor & Sports | D14: Camping Gear | E14: SUP005 | F14: 244.54 | G14: 455.48 | I14: Office Supplies | J14: 131.58455 | K14: 242.94114 | L14: =GETPIVOTDATA("Average of unit_price",$I$10,"category","Office Supplies")-GETPIVOTDATA("Average of unit_cost",$I$10,"category","Office Supplies") -> 111.35659
A15: P0014 | B15: Cycling Rest Plus | C15: Outdoor & Sports | D15: Cycling | E15: SUP007 | F15: 67.73 | G15: 152.62 | I15: Outdoor & Sports | J15: 128.27623 | K15: 240.70868 | L15: =GETPIVOTDATA("Average of unit_price",$I$10,"category","Outdoor & Sports")-GETPIVOTDATA("Average of unit_cost",$I$10,"category","Outdoor & Sports") -> 112.43245
A16: P0015 | B16: Wellness Value Plus | C16: Health & Beauty | D16: Wellness | E16: SUP022 | F16: 173.09 | G16: 358.28 | I16: Grand Total | J16: 133.86235 | K16: 246.4991
A17: P0016 | B17: Filing Not Max | C17: Office Supplies | D17: Filing | E17: SUP008 | F17: 225.1 | G17: 398.25
A18: P0017 | B18: Smart Home Social Basic | C18: Electronics | D18: Smart Home | E18: SUP008 | F18: 7.22 | G18: 13.62
A19: P0018 | B19: Headphones Example Pro | C19: Electronics | D19: Headphones | E19: SUP002 | F19: 177.54 | G19: 233.95
A20: P0019 | B20: Paper Products Specific Plus | C20: Office Supplies | D20: Paper Products | E20: SUP007 | F20: 129.51 | G20: 203.36
A21: P0020 | B21: Skincare Put Basic | C21: Health & Beauty | D21: Skincare | E21: SUP016 | F21: 181.39 | G21: 410.8
A22: P0021 | B22: Lighting Grow Pro | C22: Home & Kitchen | D22: Lighting | E22: SUP022 | F22: 202.26 | G22: 297.11
A23: P0022 | B23: Fitness Brother | C23: Outdoor & Sports | D23: Fitness | E23: SUP002 | F23: 107.05 | G23: 191.31
A24: P0023 | B24: Headphones Finally Pro | C24: Electronics | D24: Headphones | E24: SUP008 | F24: 101.85 | G24: 167.05
A25: P0024 | B25: Small Appliances Learn Max | C25: Home & Kitchen | D25: Small Appliances | E25: SUP009 | F25: 135 | G25: 190.51
A26: P0025 | B26: Cycling Coach Basic | C26: Outdoor & Sports | D26: Cycling | E26: SUP004 | F26: 218.87 | G26: 292.56
A27: P0026 | B27: Speakers Long Max | C27: Electronics | D27: Speakers | E27: SUP006 | F27: 209.33 | G27: 494.93
A28: P0027 | B28: Winter Sports About Pro | C28: Outdoor & Sports | D28: Winter Sports | E28: SUP006 | F28: 121.38 | G28: 272.42
... A201: P0200 | B201: Wellness Administration Max | C201: Health & Beauty | D201: Wellness | E201: SUP014 | F201: 216.64 | G201: 377.95

Sheet Sup data
A1: shipment_id | B1: order_id | C1: carrier | D1: ship_date | E1: scheduled_delivery_date | F1: actual_delivery_date | G1: shipping_cost_eur | H1: delivery_status
A2: SHP0000001 | B2: ORD000104 | C2: UPS | D2: 45390 | E2: 45400 | F2: 45405 | G2: 57.47 | H2: Delivered
A3: SHP0000002 | B3: ORD000258 | C3: UPS | D3: 45275 | E3: 45282 | F3: 45289 | G3: 47.42 | H3: Delivered
A4: SHP0000003 | B4: ORD003300 | C4: DPD | D4: 44993 | E4: 44996 | F4: 45006 | G4: 48.51 | H4: delivered
A5: SHP0000004 | B5: ORD003057 | C5: DHL | D5: 45321 | E5: 45324 | F5: 45338 | G5: 53.15 | H5: DELIVERED
A6: SHP0000005 | B6: ORD000697 | C6: Matkahuolto | D6: 45239 | E6: 45246 | F6: 45246 | G6: 40.55 | H6: delivered
A7: SHP0000006 | B7: ORD004047 | C7: UPS | D7: 45620 | E7: 45623 | F7: 45625 | G7: 58.52 | H7: delivered
A8: SHP0000007 | B8: ORD005666 | C8: UPS | D8: 45310 | E8: 45315 | F8: 45323 | G8: 25.11 | H8: delivered
A9: SHP0000008 | B9: ORD003739 | C9: PostNord | D9: 44986 | E9: 44991 | F9: 44990 | G9: 61.23 | H9: delivered
A10: SHP0000009 | B10: ORD003779 | C10: PostNord | D10: 45006 | E10: 45013 | F10: 45013 | G10: 4.79 | H10: delivered
A11: SHP0000010 | B11: ORD002570 | C11: Budbee | D11: 45542 | E11: 45547 | F11: 45555 | G11: 57.47 | H11: delivered
A12: SHP0000011 | B12: ORD003191 | C12: Bring | D12: 45228 | E12: 45231 | F12: 45231 | G12: 27.82 | H12: delivered
A13: SHP0000012 | B13: ORD002284 | C13: UPS | D13: 45509 | E13: 45514 | F13: 45522 | G13: 16.29 | H13: DELIVERED
... A16: SHP0000015 | B16: ORD000802 | C16: DPD | D16: 45467 | E16: 45477 | F16: 45480 | G16: 45.08 | H16: delivered
A17: SHP0000016 | B17: ORD005834 | C17: DHL | D17: 45235 | E17: 45242 | G17: 21.44 | H17: in transit
A18: SHP0000017 | B18: ORD000840 | C18: DPD | D18: 45314 | E18: 45316 | F18: 45321 | G18: 49.57 | H18: delivered
A19: SHP0000018 | B19: ORD000004 | D19: 45588 | E19: 45595 | F19: 45594 | G19: 22.54 | H19: delivered
A20: SHP0000019 | B20: ORD005195 | C20: PostNord | D20: 45485 | E20: 45490 | G20: 46.55 | H20: in transit
A21: SHP0000020 | B21: ORD000910 | C21: PostNord | D21: 45298 | E21: 45301 | F21: 45302 | G21: 59.52 | H21: Delivered
A22: SHP0000021 | B22: ORD000910 | C22: Budbee | D22: 45296 | E22: 45306 | F22: 45308 | G22: 58.19 | H22: Delivered
A23: SHP0000022 | B23: ORD005909 | C23: Budbee | D23: 45246 | E23: 45249 | F23: 45259 | G23: 42.31 | H23: DELIVERED
A24: SHP0000023 | B24: ORD004418 | C24: PostNord | D24: 45097 | E24: 45102 | G24: 6.01 | H24: in transit
A25: SHP0000024 | B25: ORD000563 | C25: DB Schenker | D25: 45038 | E25: 45041 | F25: 45042 | G25: 10.22 | H25: DELIVERED
A26: SHP0000025 | B26: ORD000289 | C26: PostNord | D26: 45033 | E26: 45043 | G26: 15.78 | H26: IN TRANSIT
A27: SHP0000026 | B27: ORD005641 | C27: Bring | D27: 45348 | E27: 45355 | F27: 45356 | G27: 10.75 | H27: delivered
A28: SHP0000027 | B28: ORD005650 | D28: 45042 | E28: 45052 | F28: 45052 | G28: 51.79 | H28: DELIVERED
A29: SHP0000028 | B29: ORD005650 | C29: Bring | D29: 45043 | E29: 45046 | F29: 45049 | G29: 58.78 | H29: Delivered
A30: SHP0000029 | B30: ORD003814 | C30: Budbee | D30: 44987 | E30: 44994 | G30: 34.6 | H30: Cancelled
A31: SHP0000030 | B31: ORD003176 | C31: Matkahuolto | D31: 45239 | E31: 45246 | F31: 45249 | G31: 57.71 | H31: Delivered
A32: SHP0000031 | B32: ORD002824 | C32: Budbee | D32: 44982 | E32: 44989 | F32: 44991 | G32: 28.78 | H32: Delivered
A33: SHP0000032 | B33: ORD002314 | C33: Bring | D33: 45204 | E33: 45206 | F33: 45216 | G33: 26.25 | H33: delivered
A34: SHP0000033 | B34: ORD003871 | C34: UPS | D34: 44963 | E34: 44970 | F34: 44978 | G34: 6.72 | H34: delivered
A35: SHP0000034 | B35: ORD000815 | C35: UPS | D35: 45162 | E35: 45172 | F35: 45172 | G35: 26.4 | H35: delivered
A36: SHP0000035 | B36: ORD001126 | C36: Budbee | D36: 45070 | E36: 45072 | G36: 17.93 | H36: Cancelled
A37: SHP0000036 | B37: ORD002483 | C37: UPS | D37: 45144 | E37: 45151 | F37: 45154 | G37: 41.16 | H37: Delivered
A38: SHP0000037 | B38: ORD002449 | C38: UPS | D38: 45460 | E38: 45462 | G38: 35.3 | H38: CANCELLED
A39: SHP0000038 | B39: ORD004155 | C39: UPS | D39: 45150 | E39: 45155 | F39: 45155 | G39: 4.72 | H39: DELIVERED
A40: SHP0000039 | B40: ORD005273 | C40: DHL | D40: 45215 | E40: 45218 | F40: 45218 | G40: 18.31 | H40: DELIVERED
A41: SHP0000040 | B41: ORD001381 | C41: UPS | D41: 45307 | E41: 45310 | F41: 45324 | H41: delivered
A42: SHP0000041 | B42: ORD004066 | C42: PostNord | D42: 45391 | E42: 45393 | G42: 55.06 | H42: In Transit
...

Sheet suppliers
A1: supplier_id | B1: supplier_name | C1: country | D1: avg_lead_time_days | E1: reliability_rating | F1: contract_start
A2: SUP001 | B2: Rodriguez, Figueroa and Sanchez | C2: Germany | D2: 6 | E2: 4.4 | F2: 44312
A3: SUP002 | B3: Rhodes PLC | C3: Vietnam | D3: 19 | E3: 3.1 | F3: 44216
A4: SUP003 | B4: Johnson-Davis | C4: Germany | D4: 39 | E4: 3 | F4: 44482
A5: SUP004 | B5: Johnson, Gonzalez and Santos | C5: Sweden | D5: 7 | E5: 2.9 | F5: 45053
A6: SUP005 | B6: Cole LLC | C6: Vietnam | D6: 19 | E6: 3.9 | F6: 45536
A7: SUP006 | B7: Blake and Sons | C7: China | D7: 40 | E7: 3.2 | F7: 45332
A8: SUP007 | B8: Ramirez-Lewis | C8: South Korea | D8: 31 | E8: 3.3 | F8: 45452
A9: SUP008 | B9: Davis Inc | C9: Netherlands | D9: 22 | E9: 4.6 | F9: 44713
A10: SUP009 | B10: Munoz-Roman | C10: China | D10: 15 | E10: 4.3 | F10: 45390
A11: SUP010 | B11: Martinez, Nielsen and Miller | C11: Finland | D11: 22 | E11: 3.1 | F11: 44593
A12: SUP011 | B12: Montgomery, Hensley and Ray | C12: Finland | D12: 11 | E12: 3 | F12: 45344
A13: SUP012 | B13: Stanley LLC | C13: Germany | D13: 27 | E13: 4.7 | F13: 45857
... A26: SUP025 | B26: Conner Group | C26: South Korea | D26: 19 | E26: 4.3 | F26: 45147

Sheet warehouses
A1: warehouse_id | B1: warehouse_name | C1: city | D1: country | E1: capacity_units
A2: WH01 | B2: Helsinki DC | C2: Helsinki | D2: Finland | E2: 27331
A3: WH02 | B3: Jyvaskyla Regional Hub | C3: Jyvaskyla | D3: Finland | E3: 50021
A4: WH03 | B4: Stockholm DC | C4: Stockholm | D4: Sweden | E4: 24207
A5: WH04 | B5: Oslo DC | C5: Oslo | D5: Norway | E5: 61347
A6: WH05 | B6: Copenhagen DC | C6: Copenhagen | D6: Denmark | E6: 72581
A7: WH06 | B7: Tallinn Hub | C7: Tallinn | D7: Estonia | E7: 55093
A8: WH07 | B8: Riga Hub | C8: Riga | D8: Latvia | E8: 28675
A9: WH08 | B9: Gdansk DC | C9: Gdansk | D9: Poland | E9: 47653
A10: WH09 | B10: Berlin DC | C10: Berlin | D10: Germany | E10: 61245
A11: WH10 | B11: Amsterdam DC | C11: Amsterdam | D11: Netherlands | E11: 47869

Sheet order_items
A1: order_item_id | B1: order_id | C1: Date | D1: Month | E1: Category | F1: product_id | G1: warehouse_id | H1: quantity | I1: unit_price | J1: discount
A2: OI0000001 | B2: ORD000104 | C2: =_xlfn.XLOOKUP(order_items[[#This Row],[order_id]],orders!A:A,orders!C:C) -> 45387 | D2: =YEAR(order_items[[#This Row],[Date]])&"-"&TEXT(MONTH(order_items[[#This Row],[Date]]),"00") -> 2024-04 | E2: =_xlfn.XLOOKUP(order_items[[#This Row],[product_id]],products!A:A,products!C:C) -> Outdoor & Sports | F2: P0088 | G2: WH06 | H2: 9 | I2: 374.4 | J2: 0.05
A3: OI0000002 | B3: ORD000258 | C3: =_xlfn.XLOOKUP(order_items[[#This Row],[order_id]],orders!A:A,orders!C:C) -> 45274 | D3: =YEAR(order_items[[#This Row],[Date]])&"-"&TEXT(MONTH(order_items[[#This Row],[Date]]),"00") -> 2023-12 | E3: =_xlfn.XLOOKUP(order_items[[#This Row],[product_id]],products!A:A,products!C:C) -> Outdoor & Sports | F3: P0059 | G3: WH06 | H3: 4 | I3: 285.12 | J3: 0.15
A4: OI0000003 | B4: ORD000258 | C4: =_xlfn.XLOOKUP(order_items[[#This Row],[order_id]],orders!A:A,orders!C:C) -> 45274 | D4: =YEAR(order_items[[#This Row],[Date]])&"-"&TEXT(MONTH(order_items[[#This Row],[Date]]),"00") -> 2023-12 | E4: =_xlfn.XLOOKUP(order_items[[#This Row],[product_id]],products!A:A,products!C:C) -> Outdoor & Sports | F4: P0004 | G4: WH08 | H4: 17 | I4: 424.37 | J4: 0
A5: OI0000004 | B5: ORD000258 | C5: =_xlfn.XLOOKUP(order_items[[#This Row],[order_id]],orders!A:A,orders!C:C) -> 45274 | D5: =YEAR(order_items[[#This Row],[Date]])&"-"&TEXT(MONTH(order_items[[#This Row],[Date]]),"00") -> 2023-12 | E5: =_xlfn.XLOOKUP(order_items[[#This Row],[product_id]],products!A:A,products!C:C) -> Health & Beauty | F5: P0189 | G5: WH03 | H5: 6 | I5: 322.11 | J5: 0
A6: OI0000005 | B6: ORD003300 | C6: =_xlfn.XLOOKUP(order_items[[#This Row],[order_id]],orders!A:A,orders!C:C) -> 44991 | D6: =YEAR(order_items[[#This Row],[Date]])&"-"&TEXT(MONTH(order_items[[#This Row],[Date]]),"00") -> 2023-03 | E6: =_xlfn.XLOOKUP(order_items[[#This Row],[product_id]],products!A:A,products!C:C) -> Electronics | F6: P0187 | G6: WH02 | H6: 5 | I6: 312.08 | J6: 0
A7: OI0000006 | B7: ORD003300 | C7: =_xlfn.XLOOKUP(order_items[[#This Row],[order_id]],orders!A:A,orders!C:C) -> 44991 | D7: =YEAR(order_items[[#This Row],[Date]])&"-"&TEXT(MONTH(order_items[[#This Row],[Date]]),"00") -> 2023-03 | E7: =_xlfn.XLOOKUP(order_items[[#This Row],[product_id]],products!A:A,products!C:C) -> Home & Kitchen | F7: P0171 | G7: WH08 | H7: 24 | I7: 450.56 | J7: 0
A8: OI0000007 | B8: ORD003057 | C8: =_xlfn.XLOOKUP(order_items[[#This Row],[order_id]],orders!A:A,orders!C:C) -> 45321 | D8: =YEAR(order_items[[#This Row],[Date]])&"-"&TEXT(MONTH(order_items[[#This Row],[Date]]),"00") -> 2024-01 | E8: =_xlfn.XLOOKUP(order_items[[#This Row],[product_id]],products!A:A,products!C:C) -> Home & Kitchen | F8: P0150 | G8: WH05 | H8: 15 | I8: 218.39 | J8: 0
A9: OI0000008 | B9: ORD003057 | C9: =_xlfn.XLOOKUP(order_items[[#This Row],[order_id]],orders!A:A,orders!C:C) -> 45321 | D9: =YEAR(order_items[[#This Row],[Date]])&"-"&TEXT(MONTH(order_items[[#This Row],[Date]]),"00") -> 2024-01 | E9: =_xlfn.XLOOKUP(order_items[[#This Row],[product_id]],products!A:A,products!C:C) -> Health & Beauty | F9: P0113 | G9: WH07 | H9: 14 | I9: 98.57 | J9: 0
A10: OI0000009 | B10: ORD003057 | C10: =_xlfn.XLOOKUP(order_items[[#This Row],[order_id]],orders!A:A,orders!C:C) -> 45321 | D10: =YEAR(order_items[[#This Row],[Date]])&"-"&TEXT(MONTH(order_items[[#This Row],[Date]]),"00") -> 2024-01 | E10: =_xlfn.XLOOKUP(order_items[[#This Row],[product_id]],products!A:A,products!C:C) -> Health & Beauty | F10: P0034 | G10: WH01 | H10: 24 | I10: 306.07 | J10: 0.05
A11: OI0000010 | B11: ORD000697 | C11: =_xlfn.XLOOKUP(order_items[[#This Row],[order_id]],orders!A:A,orders!C:C) -> 45237 | D11: =YEAR(order_items[[#This Row],[Date]])&"-"&TEXT(MONTH(order_items[[#This Row],[Date]]),"00") -> 2023-11 | E11: =_xlfn.XLOOKUP(order_items[[#This Row],[product_id]],products!A:A,products!C:C) -> Electronics | F11: P0138 | G11: WH10 | H11: 9 | I11: 152.98 | J11: 0.1
A12: OI0000011 | B12: ORD000697 | C12: =_xlfn.XLOOKUP(order_items[[#This Row],[order_id]],orders!A:A,orders!C:C) -> 45237 | D12: =YEAR(order_items[[#This Row],[Date]])&"-"&TEXT(MONTH(order_items[[#This Row],[Date]]),"00") -> 2023-11 | E12: =_xlfn.XLOOKUP(order_items[[#This Row],[product_id]],products!A:A,products!C:C) -> Home & Kitchen | F12: P0060 | G12: WH07 | H12: 17 | I12: 255.1 | J12: 0.05
A13: OI0000012 | B13: ORD004047 | C13: =_xlfn.XLOOKUP(order_items[[#This Row],[order_id]],orders!A:A,orders!C:C) -> 45618 | D13: =YEAR(order_items[[#This Row],[Date]])&"-"&TEXT(MONTH(order_items[[#This Row],[Date]]),"00") -> 2024-11 | E13: =_xlfn.XLOOKUP(order_items[[#This Row],[product_id]],products!A:A,products!C:C) -> Electronics | F13: P0158 | G13: WH01 | H13: 3 | I13: 519.7 | J13: 0.05
... A16: OI0000015 | B16: ORD005666 | C16: =_xlfn.XLOOKUP(order_items[[#This Row],[order_id]],orders!A:A,orders!C:C) -> 45308 | D16: =YEAR(order_items[[#This Row],[Date]])&"-"&TEXT(MONTH(order_items[[#This Row],[Date]]),"00") -> 2024-01 | E16: =_xlfn.XLOOKUP(order_items[[#This Row],[product_id]],products!A:A,products!C:C) -> Health & Beauty | F16: P0030 | G16: WH10 | H16: 6 | I16: 246.7 | J16: 0
A17: OI0000016 | B17: ORD005666 | C17: =_xlfn.XLOOKUP(order_items[[#This Row],[order_id]],orders!A:A,orders!C:C) -> 45308 | D17: =YEAR(order_items[[#This Row],[Date]])&"-"&TEXT(MONTH(order_items[[#This Row],[Date]]),"00") -> 2024-01 | E17: =_xlfn.XLOOKUP(order_items[[#This Row],[product_id]],products!A:A,products!C:C) -> Electronics | F17: P0133 | G17: WH03 | H17: 18 | I17: 237.27 | J17: 0.15 | L17: Sum of quantity | M17: Column Labels
A18: OI0000017 | B18: ORD003739 | C18: =_xlfn.XLOOKUP(order_items[[#This Row],[order_id]],orders!A:A,orders!C:C) -> 44983 | D18: =YEAR(order_items[[#This Row],[Date]])&"-"&TEXT(MONTH(order_items[[#This Row],[Date]]),"00") -> 2023-02 | E18: =_xlfn.XLOOKUP(order_items[[#This Row],[product_id]],products!A:A,products!C:C) -> Office Supplies | F18: P0188 | G18: WH03 | H18: 17 | I18: 532.79 | J18: 0 | L18: Row Labels | M18: Electronics | N18: Health & Beauty | O18: Home & Kitchen | P18: Office Supplies | Q18: Outdoor & Sports | R18: Grand Total
A19: OI0000018 | B19: ORD003779 | C19: =_xlfn.XLOOKUP(order_items[[#This Row],[order_id]],orders!A:A,orders!C:C) -> 45003 | D19: =YEAR(order_items[[#This Row],[Date]])&"-"&TEXT(MONTH(order_items[[#This Row],[Date]]),"00") -> 2023-03 | E19: =_xlfn.XLOOKUP(order_items[[#This Row],[product_id]],products!A:A,products!C:C) -> Health & Beauty | F19: P0067 | G19: WH05 | H19: 10 | I19: 59 | J19: 0 | L19: 2023-01 | M19: 893 | N19: 1114 | O19: 945 | P19: 1536 | Q19: 1357 | R19: 5845
A20: OI0000019 | B20: ORD003779 | C20: =_xlfn.XLOOKUP(order_items[[#This Row],[order_id]],orders!A:A,orders!C:C) -> 45003 | D20: =YEAR(order_items[[#This Row],[Date]])&"-"&TEXT(MONTH(order_items[[#This Row],[Date]]),"00") -> 2023-03 | E20: =_xlfn.XLOOKUP(order_items[[#This Row],[product_id]],products!A:A,products!C:C) -> Office Supplies | F20: P0167 | G20: WH08 | H20: 25 | I20: 490.76 | J20: 0.05 | L20: 2023-02 | M20: 883 | N20: 1255 | O20: 1183 | P20: 1339 | Q20: 1710 | R20: 6370
A21: OI0000020 | B21: ORD002570 | C21: =_xlfn.XLOOKUP(order_items[[#This Row],[order_id]],orders!A:A,orders!C:C) -> 45541 | D21: =YEAR(order_items[[#This Row],[Date]])&"-"&TEXT(MONTH(order_items[[#This Row],[Date]]),"00") -> 2024-09 | E21: =_xlfn.XLOOKUP(order_items[[#This Row],[product_id]],products!A:A,products!C:C) -> Office Supplies | F21: P0045 | G21: WH02 | H21: 10 | I21: 350.18 | J21: 0.15 | L21: 2023-03 | M21: 1120 | N21: 1295 | O21: 1085 | P21: 1430 | Q21: 1578 | R21: 6508
A22: OI0000021 | B22: ORD002570 | C22: =_xlfn.XLOOKUP(order_items[[#This Row],[order_id]],orders!A:A,orders!C:C) -> 45541 | D22: =YEAR(order_items[[#This Row],[Date]])&"-"&TEXT(MONTH(order_items[[#This Row],[Date]]),"00") -> 2024-09 | E22: =_xlfn.XLOOKUP(order_items[[#This Row],[product_id]],products!A:A,products!C:C) -> Outdoor & Sports | F22: P0075 | G22: WH08 | H22: 15 | I22: 101.7 | J22: 0.05 | L22: 2023-04 | M22: 1077 | N22: 1114 | O22: 997 | P22: 1486 | Q22: 1679 | R22: 6353
A23: OI0000022 | B23: ORD003191 | C23: =_xlfn.XLOOKUP(order_items[[#This Row],[order_id]],orders!A:A,orders!C:C) -> 45227 | D23: =YEAR(order_items[[#This Row],[Date]])&"-"&TEXT(MONTH(order_items[[#This Row],[Date]]),"00") -> 2023-10 | E23: =_xlfn.XLOOKUP(order_items[[#This Row],[product_id]],products!A:A,products!C:C) -> Health & Beauty | F23: P0148 | G23: WH04 | H23: 9 | I23: 175.38 | J23: 0 | L23: 2023-05 | M23: 1105 | N23: 1391 | O23: 866 | P23: 1261 | Q23: 1672 | R23: 6295
A24: OI0000023 | B24: ORD003191 | C24: =_xlfn.XLOOKUP(order_items[[#This Row],[order_id]],orders!A:A,orders!C:C) -> 45227 | D24: =YEAR(order_items[[#This Row],[Date]])&"-"&TEXT(MONTH(order_items[[#This Row],[Date]]),"00") -> 2023-10 | E24: =_xlfn.XLOOKUP(order_items[[#This Row],[product_id]],products!A:A,products!C:C) -> Office Supplies | F24: P0191 | G24: WH07 | H24: 16 | I24: 65.73 | J24: 0.1 | L24: 2023-06 | M24: 1172 | N24: 804 | O24: 623 | P24: 1060 | Q24: 1372 | R24: 5031
A25: OI0000024 | B25: ORD002284 | C25: =_xlfn.XLOOKUP(order_items[[#This Row],[order_id]],orders!A:A,orders!C:C) -> 45509 | D25: =YEAR(order_items[[#This Row],[Date]])&"-"&TEXT(MONTH(order_items[[#This Row],[Date]]),"00") -> 2024-08 | E25: =_xlfn.XLOOKUP(order_items[[#This Row],[product_id]],products!A:A,products!C:C) -> Office Supplies | F25: P0144 | G25: WH04 | H25: 5 | I25: 189.58 | J25: 0.15 | L25: 2023-07 | M25: 1044 | N25: 876 | O25: 1014 | P25: 1301 | Q25: 1402 | R25: 5637
A26: OI0000025 | B26: ORD004946 | C26: =_xlfn.XLOOKUP(order_items[[#This Row],[order_id]],orders!A:A,orders!C:C) -> 45341 | D26: =YEAR(order_items[[#This Row],[Date]])&"-"&TEXT(MONTH(order_items[[#This Row],[Date]]),"00") -> 2024-02 | E26: =_xlfn.XLOOKUP(order_items[[#This Row],[product_id]],products!A:A,products!C:C) -> Health & Beauty | F26: P0140 | G26: WH02 | H26: 25 | I26: 406.99 | J26: 0 | L26: 2023-08 | M26: 1065 | N26: 1214 | O26: 964 | P26: 1101 | Q26: 1727 | R26: 6071
A27: OI0000026 | B27: ORD004946 | C27: =_xlfn.XLOOKUP(order_items[[#This Row],[order_id]],orders!A:A,orders!C:C) -> 45341 | D27: =YEAR(order_items[[#This Row],[Date]])&"-"&TEXT(MONTH(order_items[[#This Row],[Date]]),"00") -> 2024-02 | E27: =_xlfn.XLOOKUP(order_items[[#This Row],[product_id]],products!A:A,products!C:C) -> Home & Kitchen | F27: P0127 | G27: WH09 | H27: 6 | I27: 45.95 | J27: 0 | L27: 2023-09 | M27: 984 | N27: 1050 | O27: 1056 | P27: 1297 | Q27: 1499 | R27: 5886
A28: OI0000027 | B28: ORD004946 | C28: =_xlfn.XLOOKUP(order_items[[#This Row],[order_id]],orders!A:A,orders!C:C) -> 45341 | D28: =YEAR(order_items[[#This Row],[Date]])&"-"&TEXT(MONTH(order_items[[#This Row],[Date]]),"00") -> 2024-02 | E28: =_xlfn.XLOOKUP(order_items[[#This Row],[product_id]],products!A:A,products!C:C) -> Electronics | F28: P0133 | G28: WH07 | H28: 4 | I28: 237.27 | J28: 0.05 | L28: 2023-10 | M28: 1097 | N28: 1150 | O28: 884 | P28: 1477 | Q28: 1709 | R28: 6317
A29: OI0000028 | B29: ORD000875 | C29: =_xlfn.XLOOKUP(order_items[[#This Row],[order_id]],orders!A:A,orders!C:C) -> 45329 | D29: =YEAR(order_items[[#This Row],[Date]])&"-"&TEXT(MONTH(order_items[[#This Row],[Date]]),"00") -> 2024-02 | E29: =_xlfn.XLOOKUP(order_items[[#This Row],[product_id]],products!A:A,products!C:C) -> Outdoor & Sports | F29: P0182 | G29: WH06 | H29: 11 | I29: 220.15 | J29: 0.15 | L29: 2023-11 | M29: 1167 | N29: 1200 | O29: 946 | P29: 1017 | Q29: 1687 | R29: 6017
A30: OI0000029 | B30: ORD000802 | C30: =_xlfn.XLOOKUP(order_items[[#This Row],[order_id]],orders!A:A,orders!C:C) -> 45466 | D30: =YEAR(order_items[[#This Row],[Date]])&"-"&TEXT(MONTH(order_items[[#This Row],[Date]]),"00") -> 2024-06 | E30: =_xlfn.XLOOKUP(order_items[[#This Row],[product_id]],products!A:A,products!C:C) -> Health & Beauty | F30: P0198 | G30: WH09 | H30: 17 | I30: 301.5 | J30: 0 | L30: 2023-12 | M30: 1125 | N30: 1190 | O30: 1076 | P30: 1392 | Q30: 2011 | R30: 6794
... A42: OI0000041 | B42: ORD004418 | C42: =_xlfn.XLOOKUP(order_items[[#This Row],[order_id]],orders!A:A,orders!C:C) -> 45094 | D42: =YEAR(order_items[[#This Row],[Date]])&"-"&TEXT(MONTH(order_items[[#This Row],[Date]]),"00") -> 2023-06 | E42: =_xlfn.XLOOKUP(order_items[[#This Row],[product_id]],products!A:A,products!C:C) -> Electronics | F42: P0055 | G42: WH06 | H42: 18 | I42: 163.53 | J42: 0.1 | L42: Grand Total | M42: 25053 | N42: 25843 | O42: 22224 | P42: 31099 | Q42: 37792 | R42: 142011
A43: OI0000042 | B43: ORD000563 | C43: =_xlfn.XLOOKUP(order_items[[#This Row],[order_id]],orders!A:A,orders!C:C) -> 45035 | D43: =YEAR(order_items[[#This Row],[Date]])&"-"&TEXT(MONTH(order_items[[#This Row],[Date]]),"00") -> 2023-04 | E43: =_xlfn.XLOOKUP(order_items[[#This Row],[product_id]],products!A:A,products!C:C) -> Electronics | F43: P0187 | G43: WH04 | H43: 23 | I43: 312.08 | J43: 0
A44: OI0000043 | B44: ORD000563 | C44: =_xlfn.XLOOKUP(order_items[[#This Row],[order_id]],orders!A:A,orders!C:C) -> 45035 | D44: =YEAR(order_items[[#This Row],[Date]])&"-"&TEXT(MONTH(order_items[[#This Row],[Date]]),"00") -> 2023-04 | E44: =_xlfn.XLOOKUP(order_items[[#This Row],[product_id]],products!A:A,products!C:C) -> Outdoor & Sports | F44: P0169 | G44: WH08 | H44: 23 | I44: 294.41 | J44: 0.15
A45: OI0000044 | B45: ORD000289 | C45: =_xlfn.XLOOKUP(order_items[[#This Row],[order_id]],orders!A:A,orders!C:C) -> 45031 | D45: =YEAR(order_items[[#This Row],[Date]])&"-"&TEXT(MONTH(order_items[[#This Row],[Date]]),"00") -> 2023-04 | E45: =_xlfn.XLOOKUP(order_items[[#This Row],[product_id]],products!A:A,products!C:C) -> Outdoor & Sports | F45: P0069 | G45: WH01 | H45: 10 | I45: 260.81 | J45: 0.1
A46: OI0000045 | B46: ORD005641 | C46: =_xlfn.XLOOKUP(order_items[[#This Row],[order_id]],orders!A:A,orders!C:C) -> 45346 | D46: =YEAR(order_items[[#This Row],[Date]])&"-"&TEXT(MONTH(order_items[[#This Row],[Date]]),"00") -> 2024-02 | E46: =_xlfn.XLOOKUP(order_items[[#This Row],[product_id]],products!A:A,products!C:C) -> Outdoor & Sports | F46: P0004 | G46: WH07 | H46: 15 | I46: 424.37 | J46: 0.1
A47: OI0000046 | B47: ORD005650 | C47: =_xlfn.XLOOKUP(order_items[[#This Row],[order_id]],orders!A:A,orders!C:C) -> 45041 | D47: =YEAR(order_items[[#This Row],[Date]])&"-"&TEXT(MONTH(order_items[[#This Row],[Date]]),"00") -> 2023-04 | E47: =_xlfn.XLOOKUP(order_items[[#This Row],[product_id]],products!A:A,products!C:C) -> Health & Beauty | F47: P0113 | G47: WH10 | H47: 8 | I47: 98.57 | J47: 0.05
A48: OI0000047 | B48: ORD005650 | C48: =_xlfn.XLOOKUP(order_items[[#This Row],[order_id]],orders!A:A,orders!C:C) -> 45041 | D48: =YEAR(order_items[[#This Row],[Date]])&"-"&TEXT(MONTH(order_items[[#This Row],[Date]]),"00") -> 2023-04 | E48: =_xlfn.XLOOKUP(order_items[[#This Row],[product_id]],products!A:A,products!C:C) -> Office Supplies | F48: P0039 | G48: WH09 | H48: 1 | I48: 207.47 | J48: 0 | L48: Row Labels | M48: Average of unit_price
A49: OI0000048 | B49: ORD003814 | C49: =_xlfn.XLOOKUP(order_items[[#This Row],[order_id]],orders!A:A,orders!C:C) -> 44984 | D49: =YEAR(order_items[[#This Row],[Date]])&"-"&TEXT(MONTH(order_items[[#This Row],[Date]]),"00") -> 2023-02 | E49: =_xlfn.XLOOKUP(order_items[[#This Row],[product_id]],products!A:A,products!C:C) -> Outdoor & Sports | F49: P0110 | G49: WH10 | H49: 6 | I49: 118.24 | J49: 0.05 | L49: Electronics | M49: 227.5842
A50: OI0000049 | B50: ORD003176 | C50: =_xlfn.XLOOKUP(order_items[[#This Row],[order_id]],orders!A:A,orders!C:C) -> 45239 | D50: =YEAR(order_items[[#This Row],[Date]])&"-"&TEXT(MONTH(order_items[[#This Row],[Date]]),"00") -> 2023-11 | E50: =_xlfn.XLOOKUP(order_items[[#This Row],[product_id]],products!A:A,products!C:C) -> Health & Beauty | F50: P0010 | G50: WH02 | H50: 7 | I50: 86.23 | J50: 0 | L50: Health & Beauty | M50: 274.91569
A51: OI0000050 | B51: ORD003176 | C51: =_xlfn.XLOOKUP(order_items[[#This Row],[order_id]],orders!A:A,orders!C:C) -> 45239 | D51: =YEAR(order_items[[#This Row],[Date]])&"-"&TEXT(MONTH(order_items[[#This Row],[Date]]),"00") -> 2023-11 | E51: =_xlfn.XLOOKUP(order_items[[#This Row],[product_id]],products!A:A,products!C:C) -> Electronics | F51: P0118 | G51: WH05 | H51: 16 | I51: 237.19 | J51: 0.1 | L51: Home & Kitchen | M51: 245.43526
A52: OI0000051 | B52: ORD002824 | C52: =_xlfn.XLOOKUP(order_items[[#This Row],[order_id]],orders!A:A,orders!C:C) -> 44979 | D52: =YEAR(order_items[[#This Row],[Date]])&"-"&TEXT(MONTH(order_items[[#This Row],[Date]]),"00") -> 2023-02 | E52: =_xlfn.XLOOKUP(order_items[[#This Row],[product_id]],products!A:A,products!C:C) -> Health & Beauty | F52: P0198 | G52: WH10 | H52: 10 | I52: 301.5 | J52: 0.15 | L52: Office Supplies | M52: 238.86224
A53: OI0000052 | B53: ORD002824 | C53: =_xlfn.XLOOKUP(order_items[[#This Row],[order_id]],orders!A:A,orders!C:C) -> 44979 | D53: =YEAR(order_items[[#This Row],[Date]])&"-"&TEXT(MONTH(order_items[[#This Row],[Date]]),"00") -> 2023-02 | E53: =_xlfn.XLOOKUP(order_items[[#This Row],[product_id]],products!A:A,products!C:C) -> Office Supplies | F53: P0092 | G53: WH09 | H53: 12 | I53: 84.97 | J53: 0 | L53: Outdoor & Sports | M53: 242.83236
...

Sheet Demand Forecast
C2: Forecast(t) = a × Actual(t-1) + (1-a) × Forecast(t-1)
E7: a | F7: =0.1 -> 0.1 | W7: a | X7: 0.28 | AK7: Category | AL7: Model | AM7: MAPE
A8: Month | B8: Category | C8: Actual | D8: SET | E8: MOVING AVG 3. MONTHS | F8: % error per month | G8: Simple Exponential Smoothing | H8: % error per month | I8: Holt-Winters Seasonal Method | J8: % error per month | S8: Month | T8: Category | U8: Actual | V8: SET | W8: MOVING AVG 3. MONTHS | X8: % error per month | Y8: Simple Exponential Smoothing | Z8: % error per month | AA8: Holt-Winters Seasonal Method | AB8: % error per month | AK8: Electronics | AL8: MOVING AVG 3. MONTHS | AM8: =O72 -> 0.18109327
A9: 44927 | B9: Outdoor & Sports | C9: 1357 | D9: TRAIN | G9: 1357 | L9: Model | M9: MAPE | S9: 44927 | T9: Health & Beauty | U9: 1114 | V9: TRAIN | Y9: 1114 | AD9: Model | AE9: MAPE | AK9: Electronics | AL9: Simple Exponential Smoothing | AM9: =O73 -> 0.17084664
A10: 44958 | B10: Outdoor & Sports | C10: 1710 | D10: TRAIN | G10: 1357 | L10: Moving Averge (3 Month) | M10: 0.16091558 | S10: 44958 | T10: Health & Beauty | U10: 1255 | V10: TRAIN | Y10: 1114 | AD10: Moving Averge (3 Month) | AE10: 0.094064971 | AK10: Electronics | AL10: Holt-Winters Seasonal Method | AM10: =O74 -> 0.15808821
A11: 44986 | B11: Outdoor & Sports | C11: 1578 | D11: TRAIN | G11: 1392.3 | L11: Simple Exponential Smoothing (a=0.5) | M11: 0.14669117 | S11: 44986 | T11: Health & Beauty | U11: 1295 | V11: TRAIN | Y11: 1153.5 | AD11: Simple Exponential Smoothing (a=0.3) | AE11: 0.086360839 | AK11: Health & Beauty | AL11: MOVING AVG 3. MONTHS | AM11: =AG17 -> 0.094064971
A12: 45017 | B12: Outdoor & Sports | C12: 1679 | D12: TRAIN | G12: 1410.9 | L12: Simple Exponential Smoothing (a=0.8) | M12: 0.1336 | S12: 45017 | T12: Health & Beauty | U12: 1114 | V12: TRAIN | Y12: 1193.1 | AD12: Simple Exponential Smoothing (a=0.28) | AE12: 0.086236091 | AK12: Health & Beauty | AL12: Simple Exponential Smoothing | AM12: =AG18 -> 0.086236091
A13: 45047 | B13: Outdoor & Sports | C13: 1672 | D13: TRAIN | G13: 1437.7 | L13: Simple Exponential Smoothing (a=0.2) | M13: 0.1336 | S13: 45047 | T13: Health & Beauty | U13: 1391 | V13: TRAIN | Y13: 1171 | AD13: Simple Exponential Smoothing (a=0.4) | AE13: 0.088523077 | AK13: Health & Beauty | AL13: Holt-Winters Seasonal Method | AM13: =AG19 -> 0.10727702
A14: 45078 | B14: Outdoor & Sports | C14: 1372 | D14: TRAIN | G14: 1461.1 | L14: Simple Exponential Smoothing (a=0.15) | M14: 0.1286 | S14: 45078 | T14: Health & Beauty | U14: 804 | V14: TRAIN | Y14: 1232.6 | AD14: Simple Exponential Smoothing (a=0.15) | AE14: 0.087951776 | AK14: Home & Kitchen | AL14: MOVING AVG 3. MONTHS | AM14: 0.19659204
A15: 45108 | B15: Outdoor & Sports | C15: 1402 | D15: TRAIN | G15: 1452.2 | L15: Simple Exponential Smoothing (a=0.1) | M15: 0.1242 | S15: 45108 | T15: Health & Beauty | U15: 876 | V15: TRAIN | Y15: 1112.6 | AD15: Simple Exponential Smoothing (a=0.1) | AE15: 0.089360883 | AK15: Home & Kitchen | AL15: Simple Exponential Smoothing | AM15: 0.16217634
A16: 45139 | B16: Outdoor & Sports | C16: 1727 | D16: TRAIN | G16: 1447.2 | L16: Simple Exponential Smoothing (a=0.05) | M16: 0.12867091 | N16: Model | O16: MAPE | P16: Total Cost (6 months) | S16: 45139 | T16: Health & Beauty | U16: 1214 | V16: TRAIN | Y16: 1046.4 | AD16: Simple Exponential Smoothing (a=0.01) | AE16: 0.087922527 | AF16: Model | AG16: MAPE | AH16: Total Cost (6 months) | AK16: Home & Kitchen | AL16: Holt-Winters Seasonal Method | AM16: 0.24810034
A17: 45170 | B17: Outdoor & Sports | C17: 1499 | D17: TRAIN | G17: 1475.2 | N17: MOVING AVG 3. MONTHS | O17: 0.16091558 | P17: 98106.3 | S17: 45170 | T17: Health & Beauty | U17: 1050 | V17: TRAIN | Y17: 1093.3 | AF17: MOVING AVG 3. MONTHS | AG17: 0.094064971 | AH17: 32390.603 | AK17: Office Supplies | AL17: MOVING AVG 3. MONTHS | AM17: =AG47 -> 0.17927731
A18: 45200 | B18: Outdoor & Sports | C18: 1709 | D18: TRAIN | G18: 1477.6 | L18: Margin | M18: 112.43245 | N18: Simple Exponential Smoothing | O18: 0.12422296 | P18: 126226.28 | S18: 45200 | T18: Health & Beauty | U18: 1150 | V18: TRAIN | Y18: 1081.2 | AD18: Margin | AE18: 122.76361 | AF18: Simple Exponential Smoothing | AG18: 0.086236091 | AH18: 20917.378 | AK18: Office Supplies | AL18: Simple Exponential Smoothing | AM18: =AG48 -> 0.14429349
A19: 45231 | B19: Outdoor & Sports | C19: 1687 | D19: TRAIN | G19: 1500.7 | L19: Holding rate | M19: 0.0167 | N19: Holt-Winters Seasonal Method | O19: 0.14694822 | P19: 97314.993 | S19: 45231 | T19: Health & Beauty | U19: 1200 | V19: TRAIN | Y19: 1100.5 | AD19: Holding rate | AE19: 0.0167 | AF19: Holt-Winters Seasonal Method | AG19: 0.10727702 | AH19: 22383.558 | AK19: Office Supplies | AL19: Holt-Winters Seasonal Method | AM19: =AG49 -> 0.12898637
A20: 45261 | B20: Outdoor & Sports | C20: 2011 | D20: TRAIN | G20: 1519.3 | L20: Unit Cost | M20: 128.27623 | S20: 45261 | T20: Health & Beauty | U20: 1190 | V20: TRAIN | Y20: 1128.4 | AD20: Unit Cost | AE20: 152.93889 | AK20: Outdoor & Sports | AL20: MOVING AVG 3. MONTHS | AM20: =O17 -> 0.16091558
A21: 45292 | B21: Outdoor & Sports | C21: 1773 | D21: TRAIN | G21: 1568.5 | S21: 45292 | T21: Health & Beauty | U21: 1348 | V21: TRAIN | Y21: 1145.6 | AK21: Outdoor & Sports | AL21: Simple Exponential Smoothing | AM21: =O18 -> 0.12422296
A22: 45323 | B22: Outdoor & Sports | C22: 1398 | D22: TRAIN | G22: 1589 | L22: Type (Moving Average) | M22: Cost Impact | N22: Type (Simple Exponential Smoothing) | O22: Cost Impact | P22: Type (Holt-Winters Seasonal Method) | Q22: Cost Impact | S22: 45323 | T22: Health & Beauty | U22: 1285 | V22: TRAIN | Y22: 1202.3 | AD22: Type (Moving Average) | AE22: Cost Impact | AF22: Type (Simple Exponential Smoothing) | AG22: Cost Impact | AH22: Type (Holt-Winters Seasonal Method) | AI22: Cost Impact | AK22: Outdoor & Sports | AL22: Holt-Winters Seasonal Method | AM22: =O19 -> 0.14694822
A23: 45352 | B23: Outdoor & Sports | C23: 1398 | D23: TRAIN | G23: 1569.9 | L23: Understock | M23: 20766.274 | N23: Understock | O23: 19293.409 | P23: Understock | Q23: 11893.931 | S23: 45352 | T23: Health & Beauty | U23: 980 | V23: TRAIN | Y23: 1225.5 | AD23: Understock | AE23: 19979.247 | AF23: Understock | AG23: 11164.543 | AH23: Understock | AI23: 14558.216
A24: 45383 | B24: Outdoor & Sports | C24: 1540 | D24: TRAIN | G24: 1552.7 | L24: Overstock | M24: 157.8811 | N24: Understock | O24: 1169.2975 | P24: Overstock | Q24: 138.93301 | S24: 45383 | T24: Health & Beauty | U24: 1035 | V24: TRAIN | Y24: 1156.8 | AD24: Overstock | AE24: 371.24551 | AF24: Overstock | AG24: 431.65592 | AH24: Overstock | AI24: 412.85278
A25: 45413 | B25: Outdoor & Sports | C25: 1731 | D25: TRAIN | G25: 1551.4 | L25: Understock | M25: 39834.818 | N25: Understock | O25: 51314.171 | P25: Understock | Q25: 44595.649 | S25: 45413 | T25: Health & Beauty | U25: 1094 | V25: TRAIN | Y25: 1122.7 | AD25: Understock | AE25: 9331.8936 | AF25: Understock | AG25: 8983.353 | AH25: Understock | AI25: 6833.817
A26: 45444 | B26: Outdoor & Sports | C26: 1741 | D26: TEST | E26: 1556.3 | F26: 0.10608845 | G26: 1569.4 | H26: 0.098564044 | I26: 1635.2126 | J26: 0.060762407 | L26: Understock | M26: 35753.52 | N26: Understock | O26: 53832.658 | P26: Understock | Q26: 39319.29 | S26: 45444 | T26: Health & Beauty | U26: 1214 | V26: TEST | W26: 1036.3 | X26: 0.14637562 | Y26: 1114.7 | Z26: 0.081795717 | AA26: 1074.3567 | AB26: 0.11502745 | AD26: Overstock | AE26: 132.8172 | AF26: Overstock | AG26: 136.03052 | AH26: Overstock | AI26: 437.52274 | AK26: Category | AL26: Model | AM26: Total Cost
A27: 45474 | B27: Outdoor & Sports | C27: 1597 | D27: TEST | E27: 1670.7 | F27: 0.046149029 | G27: 1586.6 | H27: 0.0065122104 | I27: 1661.8549 | J27: 0.040610456 | L27: Overstock | M27: 920.50892 | N27: Overstock | O27: 413.66133 | P27: Overstock | Q27: 846.93847 | S27: 45474 | T27: Health & Beauty | U27: 941 | V27: TEST | W27: 1114.3 | X27: 0.18416578 | Y27: 1142.5 | Z27: 0.2141339 | AA27: 1136.6049 | AB27: 0.2078692 | AD27: Understock | AE27: 2394.8112 | AF27: Overstock | AG27: 40.059383 | AH27: Overstock | AI27: 1.1842384 | AK27: Electronics | AL27: MOVING AVG 3. MONTHS | AM27: 50700.988
A28: 45505 | B28: Outdoor & Sports | C28: 2044 | D28: TEST | E28: 1689.7 | F28: 0.17333659 | G28: 1587.6 | H28: 0.22328767 | I28: 1647.3561 | J28: 0.1940528 | L28: Overstock | M28: 673.29754 | N28: Overstock | O28: 203.08179 | P28: Overstock | Q28: 520.25186 | S28: 45505 | T28: Health & Beauty | U28: 1166 | V28: TEST | W28: 1083 | X28: 0.071183533 | Y28: 1086.1 | Z28: 0.068524871 | AA28: 1100.4496 | AB28: 0.056218186 | AD28: Overstock | AE28: 180.58855 | AF28: Overstock | AG28: 161.73708 | AH28: Overstock | AI28: 139.9648 | AK28: Electronics | AL28: Simple Exponential Smoothing | AM28: 56754.254
A29: 45536 | B29: Outdoor & Sports | C29: 2112 | D29: TEST | E29: 1794 | F29: 0.15056818 | G29: 1633.2 | H29: 0.22670455 | I29: 1762.2852 | J29: 0.16558465 | L29: Total | M29: 98106.3 | O29: 126226.28 | Q29: 97314.993 | S29: 45536 | T29: Health & Beauty | U29: 1045 | V29: TEST | W29: 1107 | X29: 0.059330144 | Y29: 1108.5 | Z29: 0.06076555 | AA29: 1252.2933 | AB29: 0.19836676 | AD29: Total | AE29: 32390.603 | AG29: 20917.378 | AI29: 22383.558 | AK29: Electronics | AL29: Holt-Winters Seasonal Method | AM29: 39185.013
A30: 45566 | B30: Outdoor & Sports | C30: 1488 | D30: TEST | E30: 1917.7 | F30: 0.28877688 | G30: 1681.1 | H30: 0.12977151 | I30: 1883.3568 | J30: 0.26569677 | S30: 45566 | T30: Health & Beauty | U30: 1072 | V30: TEST | W30: 1050.7 | X30: 0.019869403 | Y30: 1090.7 | Z30: 0.01744403 | AA30: 1072.5611 | AB30: 0.00052339423 | AK30: Health & Beauty | AL30: MOVING AVG 3. MONTHS | AM30: 32390.603
A31: 45597 | B31: Outdoor & Sports | C31: 1567 | D31: TEST | E31: 1881.3 | F31: 0.20057435 | G31: 1661.8 | H31: 0.060497766 | I31: 1809.8572 | J31: 0.15498226 | S31: 45597 | T31: Health & Beauty | U31: 1010 | V31: TEST | W31: 1094.3 | X31: 0.083465347 | Y31: 1085.5 | Z31: 0.074752475 | AA31: 1076.3137 | AB31: 0.065657147 | AK31: Health & Beauty | AL31: Simple Exponential Smoothing | AM31: 20917.378
AK32: Health & Beauty | AL32: Holt-Winters Seasonal Method | AM32: 22383.558
A33: Mean Absolute Percentage Error | E33: MAPE | F33: 0.16091558 | H33: 0.12422296 | J33: 0.14694822 | S33: Mean Absolute Percentage Error | W33: MAPE | X33: 0.094064971 | Z33: 0.086236091 | AB33: 0.10727702 | AK33: Home & Kitchen | AL33: MOVING AVG 3. MONTHS | AM33: 49063.849
AK34: Home & Kitchen | AL34: Simple Exponential Smoothing | AM34: 63105.896
AK35: Home & Kitchen | AL35: Holt-Winters Seasonal Method | AM35: 72368.511
AK36: Office Supplies | AL36: MOVING AVG 3. MONTHS | AM36: 83309.305
E37: a | F37: 0.01 | W37: a | X37: 0.07 | AK37: Office Supplies | AL37: Simple Exponential Smoothing | AM37: 86281.092
A38: Month | B38: Category | C38: Actual | D38: SET | E38: MOVING AVG 3. MONTHS | F38: % error per month | G38: Simple Exponential Smoothing | H38: % error per month | I38: Holt-Winters Seasonal Method | J38: % error per month | S38: Month | T38: Category | U38: Actual | V38: SET | W38: MOVING AVG 3. MONTHS | X38: % error per month | Y38: Simple Exponential Smoothing | Z38: % error per month | AA38: Holt-Winters Seasonal Method | AB38: % error per month | AK38: Office Supplies | AL38: Holt-Winters Seasonal Method | AM38: 88690.39
A39: 44927 | B39: Home & Kitchen | C39: 945 | D39: TRAIN | G39: 945 | L39: Model | M39: MAPE | S39: 44927 | T39: Office Supplies | U39: 1536 | V39: TRAIN | Y39: 1536 | AD39: Model | AE39: MAPE | AK39: Outdoor & Sports | AL39: MOVING AVG 3. MONTHS | AM39: 98106.3
A40: 44958 | B40: Home & Kitchen | C40: 1183 | D40: TRAIN | G40: 945 | L40: Moving Averge (3 Month) | M40: 0.19659204 | S40: 44958 | T40: Office Supplies | U40: 1339 | V40: TRAIN | Y40: 1536 | AD40: Moving Averge (3 Month) | AE40: 0.17927731 | AK40: Outdoor & Sports | AL40: Simple Exponential Smoothing | AM40: 126226.28
A41: 44986 | B41: Home & Kitchen | C41: 1085 | D41: TRAIN | G41: 947.4 | L41: Simple Exponential Smoothing (a=0.3) | M41: 0.19669051 | S41: 44986 | T41: Office Supplies | U41: 1430 | V41: TRAIN | Y41: 1522.2 | AD41: Simple Exponential Smoothing (a=0.3) | AE41: 0.1589617 | AK41: Outdoor & Sports | AL41: Holt-Winters Seasonal Method | AM41: 97314.993
A42: 45017 | B42: Home & Kitchen | C42: 997 | D42: TRAIN | G42: 948.8 | L42: Simple Exponential Smoothing (a=0.2) | M42: 0.18700905 | S42: 45017 | T42: Office Supplies | U42: 1486 | V42: TRAIN | Y42: 1515.7 | AD42: Simple Exponential Smoothing (a=0.2) | AE42: 0.15197871
A43: 45047 | B43: Home & Kitchen | C43: 866 | D43: TRAIN | G43: 949.3 | L43: Simple Exponential Smoothing (a=0.4) | M43: 0.2065846 | S43: 45047 | T43: Office Supplies | U43: 1261 | V43: TRAIN | Y43: 1513.6 | AD43: Simple Exponential Smoothing (a=0.4) | AE43: 0.16456156
A44: 45078 | B44: Home & Kitchen | C44: 623 | D44: TRAIN | G44: 948.5 | L44: Simple Exponential Smoothing (a=0.15) | M44: 0.18229445 | S44: 45078 | T44: Office Supplies | U44: 1060 | V44: TRAIN | Y44: 1495.9 | AD44: Simple Exponential Smoothing (a=0.15) | AE44: 0.14823588
A45: 45108 | B45: Home & Kitchen | C45: 1014 | D45: TRAIN | G45: 945.2 | L45: Simple Exponential Smoothing (a=0.1) | M45: 0.17764339 | S45: 45108 | T45: Office Supplies | U45: 1301 | V45: TRAIN | Y45: 1465.4 | AD45: Simple Exponential Smoothing (a=0.1) | AE45: 0.1450948
...
